Traceback (most recent call last):
  File "/home/ryan/.conda/envs/work3-9/lib/python3.9/site-packages/jupyter_cache/executors/utils.py", line 58, in single_nb_execution
    executenb(
  File "/home/ryan/.conda/envs/work3-9/lib/python3.9/site-packages/nbclient/client.py", line 1093, in execute
    return NotebookClient(nb=nb, resources=resources, km=km, **kwargs).execute()
  File "/home/ryan/.conda/envs/work3-9/lib/python3.9/site-packages/nbclient/util.py", line 84, in wrapped
    return just_run(coro(*args, **kwargs))
  File "/home/ryan/.conda/envs/work3-9/lib/python3.9/site-packages/nbclient/util.py", line 62, in just_run
    return loop.run_until_complete(coro)
  File "/home/ryan/.conda/envs/work3-9/lib/python3.9/asyncio/base_events.py", line 642, in run_until_complete
    return future.result()
  File "/home/ryan/.conda/envs/work3-9/lib/python3.9/site-packages/nbclient/client.py", line 559, in async_execute
    await self.async_execute_cell(
  File "/home/ryan/.conda/envs/work3-9/lib/python3.9/site-packages/nbclient/client.py", line 854, in async_execute_cell
    self._check_raise_for_error(cell, exec_reply)
  File "/home/ryan/.conda/envs/work3-9/lib/python3.9/site-packages/nbclient/client.py", line 756, in _check_raise_for_error
    raise CellExecutionError.from_cell_and_msg(cell, exec_reply_content)
nbclient.exceptions.CellExecutionError: An error occurred while executing the following cell:
------------------
xy_data = np.loadtxt('../data/xy_data.csv',delimiter=',')
x=xy_data[:,0];
y=xy_data[:,1];
plt.plot(x,y,'o')
plt.xlabel('x')
plt.ylabel('y')
------------------

[0;31m---------------------------------------------------------------------------[0m
[0;31mOSError[0m                                   Traceback (most recent call last)
[0;32m<ipython-input-2-a297c57fc65a>[0m in [0;36m<module>[0;34m[0m
[0;32m----> 1[0;31m [0mxy_data[0m [0;34m=[0m [0mnp[0m[0;34m.[0m[0mloadtxt[0m[0;34m([0m[0;34m'../data/xy_data.csv'[0m[0;34m,[0m[0mdelimiter[0m[0;34m=[0m[0;34m','[0m[0;34m)[0m[0;34m[0m[0;34m[0m[0m
[0m[1;32m      2[0m [0mx[0m[0;34m=[0m[0mxy_data[0m[0;34m[[0m[0;34m:[0m[0;34m,[0m[0;36m0[0m[0;34m][0m[0;34m;[0m[0;34m[0m[0;34m[0m[0m
[1;32m      3[0m [0my[0m[0;34m=[0m[0mxy_data[0m[0;34m[[0m[0;34m:[0m[0;34m,[0m[0;36m1[0m[0;34m][0m[0;34m;[0m[0;34m[0m[0;34m[0m[0m
[1;32m      4[0m [0mplt[0m[0;34m.[0m[0mplot[0m[0;34m([0m[0mx[0m[0;34m,[0m[0my[0m[0;34m,[0m[0;34m'o'[0m[0;34m)[0m[0;34m[0m[0;34m[0m[0m
[1;32m      5[0m [0mplt[0m[0;34m.[0m[0mxlabel[0m[0;34m([0m[0;34m'x'[0m[0;34m)[0m[0;34m[0m[0;34m[0m[0m

[0;32m~/.conda/envs/work3-9/lib/python3.9/site-packages/numpy/lib/npyio.py[0m in [0;36mloadtxt[0;34m(fname, dtype, comments, delimiter, converters, skiprows, usecols, unpack, ndmin, encoding, max_rows, like)[0m
[1;32m   1063[0m             [0mfname[0m [0;34m=[0m [0mos_fspath[0m[0;34m([0m[0mfname[0m[0;34m)[0m[0;34m[0m[0;34m[0m[0m
[1;32m   1064[0m         [0;32mif[0m [0m_is_string_like[0m[0;34m([0m[0mfname[0m[0;34m)[0m[0;34m:[0m[0;34m[0m[0;34m[0m[0m
[0;32m-> 1065[0;31m             [0mfh[0m [0;34m=[0m [0mnp[0m[0;34m.[0m[0mlib[0m[0;34m.[0m[0m_datasource[0m[0;34m.[0m[0mopen[0m[0;34m([0m[0mfname[0m[0;34m,[0m [0;34m'rt'[0m[0;34m,[0m [0mencoding[0m[0;34m=[0m[0mencoding[0m[0;34m)[0m[0;34m[0m[0;34m[0m[0m
[0m[1;32m   1066[0m             [0mfencoding[0m [0;34m=[0m [0mgetattr[0m[0;34m([0m[0mfh[0m[0;34m,[0m [0;34m'encoding'[0m[0;34m,[0m [0;34m'latin1'[0m[0;34m)[0m[0;34m[0m[0;34m[0m[0m
[1;32m   1067[0m             [0mfh[0m [0;34m=[0m [0miter[0m[0;34m([0m[0mfh[0m[0;34m)[0m[0;34m[0m[0;34m[0m[0m

[0;32m~/.conda/envs/work3-9/lib/python3.9/site-packages/numpy/lib/_datasource.py[0m in [0;36mopen[0;34m(path, mode, destpath, encoding, newline)[0m
[1;32m    192[0m [0;34m[0m[0m
[1;32m    193[0m     [0mds[0m [0;34m=[0m [0mDataSource[0m[0;34m([0m[0mdestpath[0m[0;34m)[0m[0;34m[0m[0;34m[0m[0m
[0;32m--> 194[0;31m     [0;32mreturn[0m [0mds[0m[0;34m.[0m[0mopen[0m[0;34m([0m[0mpath[0m[0;34m,[0m [0mmode[0m[0;34m,[0m [0mencoding[0m[0;34m=[0m[0mencoding[0m[0;34m,[0m [0mnewline[0m[0;34m=[0m[0mnewline[0m[0;34m)[0m[0;34m[0m[0;34m[0m[0m
[0m[1;32m    195[0m [0;34m[0m[0m
[1;32m    196[0m [0;34m[0m[0m

[0;32m~/.conda/envs/work3-9/lib/python3.9/site-packages/numpy/lib/_datasource.py[0m in [0;36mopen[0;34m(self, path, mode, encoding, newline)[0m
[1;32m    529[0m                                       encoding=encoding, newline=newline)
[1;32m    530[0m         [0;32melse[0m[0;34m:[0m[0;34m[0m[0;34m[0m[0m
[0;32m--> 531[0;31m             [0;32mraise[0m [0mIOError[0m[0;34m([0m[0;34m"%s not found."[0m [0;34m%[0m [0mpath[0m[0;34m)[0m[0;34m[0m[0;34m[0m[0m
[0m[1;32m    532[0m [0;34m[0m[0m
[1;32m    533[0m [0;34m[0m[0m

[0;31mOSError[0m: ../data/xy_data.csv not found.
OSError: ../data/xy_data.csv not found.

